<?xml version="1.0"?>
<robot xmlns:xacro="http://www.ros.org/wiki/xacro" name="diffbot">
  <xacro:property name="wheel_radius" value="0.07"/>
  <xacro:property name="wheel_separation" value="0.30"/>

  <link name="base_link">
    <inertial>
      <mass value="1.0"/>
      <inertia ixx="0.1" iyy="0.1" izz="0.1" ixy="0" ixz="0" iyz="0"/>
    </inertial>
    <visual>
      <geometry><box size="0.3 0.3 0.1"/></geometry>
      <material name="blue"><color rgba="0 0 1 1"/></material>
    </visual>
    <collision><geometry><box size="0.3 0.3 0.1"/></geometry></collision>
  </link>

  <link name="left_wheel">
    <inertial>
      <mass value="0.2"/>
      <inertia ixx="0.001" iyy="0.001" izz="0.001" ixy="0" ixz="0" iyz="0"/>
    </inertial>
    <visual><geometry><cylinder length="0.05" radius="${wheel_radius}"/></geometry></visual>
    <collision><geometry><cylinder length="0.05" radius="${wheel_radius}"/></geometry></collision>
  </link>

  <link name="right_wheel">
    <inertial>
      <mass value="0.2"/>
      <inertia ixx="0.001" iyy="0.001" izz="0.001" ixy="0" ixz="0" iyz="0"/>
    </inertial>
    <visual><geometry><cylinder length="0.05" radius="${wheel_radius}"/></geometry></visual>
    <collision><geometry><cylinder length="0.05" radius="${wheel_radius}"/></geometry></collision>
  </link>

  <joint name="left_wheel_joint" type="continuous">
    <parent link="base_link"/>
    <child link="left_wheel"/>
    <origin xyz="0 0.15 0" rpy="1.5708 0 0"/>
    <axis xyz="0 1 0"/>
  </joint>

  <joint name="right_wheel_joint" type="continuous">
    <parent link="base_link"/>
    <child link="right_wheel"/>
    <origin xyz="0 -0.15 0" rpy="1.5708 0 0"/>
    <axis xyz="0 1 0"/>
  </joint>

  <gazebo>
    <plugin filename="gz_ros2_control-system" name="gz_ros2_control::GazeboSimROS2ControlPlugin">
      <robot_param>robot_description</robot_param>
      <robot_param_node>robot_state_publisher</robot_param_node>
    </plugin>
  </gazebo>

  <ros2_control name="DiffBotSystem" type="system">
    <hardware>
      <plugin>gazebo_ros2_control/DefaultRobotHWSim</plugin>
    </hardware>
    <joint name="left_wheel_joint">
      <command_interface>velocity</command_interface>
      <state_interface>position</state_interface>
      <state_interface>velocity</state_interface>
    </joint>
    <joint name="right_wheel_joint">
      <command_interface>velocity</command_interface>
      <state_interface>position</state_interface>
      <state_interface>velocity</state_interface>
    </joint>
  </ros2_control>
</robot>

