<?xml version="1.0" ?>
<!-- =================================================================================== -->
<!-- |    This document was autogenerated by xacro from urdf/diffbot.urdf.xacro        | -->
<!-- |    EDITING THIS FILE BY HAND IS NOT RECOMMENDED                                 | -->
<!-- =================================================================================== -->
<robot name="diffbot">
  <link name="base_link">
    <inertial>
      <mass value="1.0"/>
      <inertia ixx="0.1" ixy="0" ixz="0" iyy="0.1" iyz="0" izz="0.1"/>
    </inertial>
    <visual>
      <geometry>
        <box size="0.3 0.3 0.1"/>
      </geometry>
      <material name="blue">
        <color rgba="0 0 1 1"/>
      </material>
    </visual>
    <collision>
      <geometry>
        <box size="0.3 0.3 0.1"/>
      </geometry>
    </collision>
  </link>
  <link name="left_wheel">
    <inertial>
      <mass value="0.2"/>
      <inertia ixx="0.001" ixy="0" ixz="0" iyy="0.001" iyz="0" izz="0.001"/>
    </inertial>
    <visual>
      <geometry>
        <cylinder length="0.05" radius="0.07"/>
      </geometry>
      <material name="black">
        <color rgba="0 0 0 1"/>
      </material>
    </visual>
    <collision>
      <geometry>
        <cylinder length="0.05" radius="0.07"/>
      </geometry>
    </collision>
  </link>
  <link name="right_wheel">
    <inertial>
      <mass value="0.2"/>
      <inertia ixx="0.001" ixy="0" ixz="0" iyy="0.001" iyz="0" izz="0.001"/>
    </inertial>
    <visual>
      <geometry>
        <cylinder length="0.05" radius="0.07"/>
      </geometry>
      <material name="black">
        <color rgba="0 0 0 1"/>
      </material>
    </visual>
    <collision>
      <geometry>
        <cylinder length="0.05" radius="0.07"/>
      </geometry>
    </collision>
  </link>
  <joint name="left_wheel_joint" type="continuous">
    <parent link="base_link"/>
    <child link="left_wheel"/>
    <origin rpy="1.5708 0 0" xyz="0 0.15 0"/>
    <axis xyz="0 1 0"/>
  </joint>
  <joint name="right_wheel_joint" type="continuous">
    <parent link="base_link"/>
    <child link="right_wheel"/>
    <origin rpy="1.5708 0 0" xyz="0 -0.15 0"/>
    <axis xyz="0 1 0"/>
  </joint>
  <gazebo>
    <plugin filename="libgz_ros2_control_system.so" name="ros2_control"/>
  </gazebo>
  <ros2_control name="DiffBotSystem" type="system">
    <hardware>
      <plugin>gazebo_ros2_control/DefaultRobotHWSim</plugin>
    </hardware>
    <joint name="left_wheel_joint">
      <command_interface>velocity</command_interface>
      <state_interface>position</state_interface>
      <state_interface>velocity</state_interface>
    </joint>
    <joint name="right_wheel_joint">
      <command_interface>velocity</command_interface>
      <state_interface>position</state_interface>
      <state_interface>velocity</state_interface>
    </joint>
  </ros2_control>
</robot>
